Run Information
========================
cognizant.intelligent.test.scripter.engine : 1.1
java.runtime.name    : Java(TM) SE Runtime Environment
java.version         : 1.8.0_172
java.home            : C:\Program Files\Java\jre1.8.0_172
os.name              : Windows 10
os.arch              : amd64
os.version           : 10.0
file.encoding        : UTF-8
========================
Run Started on Wed May 23 14:30:38 BST 2018
Loading Browser Profile
Loading RunManager
[Scenario:Login] [TestCase: VerifyLogin] [Description: VerifyLogin] [Browser: Chrome] [BrowserVersion: Default] [Platform: ANY][ExistingBrowser: false]
----------------------------------------------------------
[1] TestCase selected for execution from [//NewRelease/NewTestSet]
----------------------------------------------------------
Initializing Report
ApiLink not available!!
Shutting Down Thread as there is no need for SelectiveThreading
Running Iteration 1
Launching Chrome
Launching Remote Driver
2018-05-23 14:30:45:05S +0100 [INFO] org.openqa.selenium.remote.ProtocolHandshake createSession:Detected dialect: OSS
Chrome Launched
Step:1   | Object: Browser | Action: Open | Input: @http://newtours.demoaut.com/mercurysignon.php | Conditon:  | @23-May-2018 14:30:45.045
[DONE]   | Opened Url: http://newtours.demoaut.com/mercurysignon.php

===================================================================================================

Step:1   | Object: userName | Action: Set | Input: TestData0:userName | Conditon:  | @23-May-2018 14:30:46.046
[DEBUG]   | Test Data Not Found, Iteration - 1 is missing. 
[Env : Default | Sheet : TestData0 | Field : userName | TestCase : Login/VerifyLogin | Reusabe : Login/Login_ReUse ]

===================================================================================================

2018-05-23 14:30:46:05S +0100 [SEVERE] com.cognizant.cognizantits.engine.core.Task onError:Error in testcase [//Login/Login_ReUse]
com.cognizant.cognizantits.engine.execution.exception.TestFailedException: Error in testcase [//Login/Login_ReUse]
	at com.cognizant.cognizantits.engine.execution.run.TestCaseRunner.onDataNotFoundException(TestCaseRunner.java:306)
	at com.cognizant.cognizantits.engine.execution.run.TestCaseRunner.run(TestCaseRunner.java:350)
	at com.cognizant.cognizantits.engine.execution.run.TestCaseRunner.run(TestCaseRunner.java:387)
	at com.cognizant.cognizantits.engine.execution.run.TestStepRunner.executeTestCase(TestStepRunner.java:137)
	at com.cognizant.cognizantits.engine.execution.run.TestStepRunner.execute(TestStepRunner.java:118)
	at com.cognizant.cognizantits.engine.execution.run.TestStepRunner.run(TestStepRunner.java:63)
	at com.cognizant.cognizantits.engine.execution.run.TestCaseRunner.runStep(TestCaseRunner.java:395)
	at com.cognizant.cognizantits.engine.execution.run.TestCaseRunner.run(TestCaseRunner.java:346)
	at com.cognizant.cognizantits.engine.core.Task.runIteration(Task.java:123)
	at com.cognizant.cognizantits.engine.core.Task.run(Task.java:81)
	at java.util.concurrent.ThreadPoolExecutor.runWorker(Unknown Source)
	at java.util.concurrent.ThreadPoolExecutor$Worker.run(Unknown Source)
	at java.lang.Thread.run(Unknown Source)
Caused by: Test Data Not Found, Iteration - 1 is missing. 
[Env : Default | Sheet : TestData0 | Field : userName | TestCase : Login/VerifyLogin | Reusabe : Login/Login_ReUse ]
	at com.cognizant.cognizantits.engine.execution.data.DataAccessInternal.throwErrorWithCause(DataAccessInternal.java:287)
	at com.cognizant.cognizantits.engine.execution.data.DataAccess.getData(DataAccess.java:71)
	at com.cognizant.cognizantits.engine.execution.data.DataProcessor.resolve(DataProcessor.java:64)
	at com.cognizant.cognizantits.engine.core.CommandControl.sync(CommandControl.java:169)
	at com.cognizant.cognizantits.engine.execution.run.TestStepRunner.executeStep(TestStepRunner.java:160)
	at com.cognizant.cognizantits.engine.execution.run.TestStepRunner.executeStep(TestStepRunner.java:147)
	at com.cognizant.cognizantits.engine.execution.run.TestStepRunner.run(TestStepRunner.java:66)
	at com.cognizant.cognizantits.engine.execution.run.TestCaseRunner.runStep(TestCaseRunner.java:395)
	at com.cognizant.cognizantits.engine.execution.run.TestCaseRunner.run(TestCaseRunner.java:346)
	... 11 more

[DEBUG]   | Error in testcase [//Login/Login_ReUse]

===================================================================================================


---------------------------------------------------
Testcase Name        : Login:VerifyLogin
Executed Steps       : 3
Passed Steps         : 1
Failed Steps         : 2
Time Taken           : 00:00:08
-----------------------------------------------------

Run Finished on Wed May 23 14:30:47 BST 2018
-----------------------------------------------------
ExecutionDate        : 23-May-2018 14-30-38
Executed TestCases   : 1
Passed TestCases     : 0
Failed TestCases     : 1
Time Taken           : 00:00:08
ReportPath           : file:///D:\cognizant-intelligent-test-scripter-1.1\Projects\DemoCITS\Results\TestExecution\NewRelease\NewTestSet\23-May-2018 14-30-38\summary.html
-----------------------------------------------------
